{
    "Modified": "2011-07-18T22:40:07.127000",
    "Published": "2010-10-19T16:00:04.237000",
    "access": {
        "authentication": "NONE",
        "complexity": "LOW",
        "vector": "NETWORK"
    },
    "cvss": "5.0",
    "cvss-time": "2010-10-20T15:24:00",
    "cwe": "Unknown",
    "id": "CVE-2010-3492",
    "impact": {
        "availability": "PARTIAL",
        "confidentiality": "NONE",
        "integrity": "NONE"
    },
    "last-modified": "2017-09-18T21:31:24.690000",
    "nessus": [
        {
            "NASL family": "Mandriva Local Security Checks",
            "NASL id": "MANDRIVA_MDVSA-2010-215.NASL",
            "description": "Multiple vulnerabilities was discovered and corrected in python :\n\nBuffer underflow in the rgbimg module in Python 2.5 allows remote attackers to cause a denial of service (application crash) via a large ZSIZE value in a black-and-white (aka B/W) RGB image that triggers an invalid pointer dereference (CVE-2009-4134).\n\nInteger overflow in rgbimgmodule.c in the rgbimg module in Python 2.5 allows remote attackers to have an unspecified impact via a large image that triggers a buffer overflow. NOTE: this vulnerability exists because of an incomplete fix for CVE-2008-3143.12 (CVE-2010-1449).\n\nMultiple buffer overflows in the RLE decoder in the rgbimg module in Python 2.5 allow remote attackers to have an unspecified impact via an image file containing crafted data that triggers improper processing within the (1) longimagedata or (2) expandrow function (CVE-2010-1450).\n\nThe asyncore module in Python before 3.2 does not properly handle unsuccessful calls to the accept function, and does not have accompanying documentation describing how daemon applications should handle unsuccessful calls to the accept function, which makes it easier for remote attackers to conduct denial of service attacks that terminate these applications via network connections (CVE-2010-3492).\n\nMultiple race conditions in smtpd.py in the smtpd module in Python 2.6, 2.7, 3.1, and 3.2 alpha allow remote attackers to cause a denial of service (daemon outage) by establishing and then immediately closing a TCP connection, leading to the accept function having an unexpected return value of None, an unexpected value of None for the address, or an ECONNABORTED, EAGAIN, or EWOULDBLOCK error, or the getpeername function having an ENOTCONN error, a related issue to CVE-2010-3492 (CVE-2010-3493).\n\nPackages for 2009.0 are provided as of the Extended Maintenance Program. Please visit this link to learn more:\nhttp://store.mandriva.com/product_info.php?cPath=149&amp;products_id=4 90\n\nThe updated packages have been patched to correct these issues.",
            "last seen": "2019-02-21",
            "modified": "2018-07-19",
            "plugin id": "50423",
            "published": "2010-11-01",
            "reporter": "Tenable",
            "source": "https://www.tenable.com/plugins/index.php?view=single&id=50423",
            "title": "Mandriva Linux Security Advisory : python (MDVSA-2010:215)"
        },
        {
            "NASL family": "Mandriva Local Security Checks",
            "NASL id": "MANDRIVA_MDVSA-2010-216.NASL",
            "description": "Multiple vulnerabilities was discovered and corrected in python :\n\nThe asyncore module in Python before 3.2 does not properly handle unsuccessful calls to the accept function, and does not have accompanying documentation describing how daemon applications should handle unsuccessful calls to the accept function, which makes it easier for remote attackers to conduct denial of service attacks that terminate these applications via network connections (CVE-2010-3492).\n\nMultiple race conditions in smtpd.py in the smtpd module in Python 2.6, 2.7, 3.1, and 3.2 alpha allow remote attackers to cause a denial of service (daemon outage) by establishing and then immediately closing a TCP connection, leading to the accept function having an unexpected return value of None, an unexpected value of None for the address, or an ECONNABORTED, EAGAIN, or EWOULDBLOCK error, or the getpeername function having an ENOTCONN error, a related issue to CVE-2010-3492 (CVE-2010-3493).\n\nThe updated packages have been patched to correct these issues.",
            "last seen": "2019-02-21",
            "modified": "2018-07-19",
            "plugin id": "50424",
            "published": "2010-11-01",
            "reporter": "Tenable",
            "source": "https://www.tenable.com/plugins/index.php?view=single&id=50424",
            "title": "Mandriva Linux Security Advisory : python (MDVSA-2010:216)"
        },
        {
            "NASL family": "Gentoo Local Security Checks",
            "NASL id": "GENTOO_GLSA-201401-04.NASL",
            "description": "The remote host is affected by the vulnerability described in GLSA-201401-04 (Python: Multiple vulnerabilities)\n\n    Multiple vulnerabilities have been discovered in Python. Please review       the CVE identifiers referenced below for details.\n  Impact :\n\n    A remote attacker could possibly cause a Denial of Service condition or       perform a man-in-the-middle attack to disclose sensitive information.\n  Workaround :\n\n    There is no known workaround at this time.",
            "last seen": "2019-02-21",
            "modified": "2018-07-12",
            "plugin id": "71811",
            "published": "2014-01-07",
            "reporter": "Tenable",
            "source": "https://www.tenable.com/plugins/index.php?view=single&id=71811",
            "title": "GLSA-201401-04 : Python: Multiple vulnerabilities"
        }
    ],
    "oval": [
        {
            "accepted": "2013-11-14T10:21:28.482-05:00",
            "class": "vulnerability",
            "contributors": [
                {
                    "name": "SecPod Team",
                    "organization": "SecPod Technologies"
                },
                {
                    "name": "Maria Kedovskaya",
                    "organization": "ALTX-SOFT"
                }
            ],
            "definition_extensions": [
                {
                    "comment": "Python is installed",
                    "oval": "oval:org.mitre.oval:def:11791"
                }
            ],
            "description": "The asyncore module in Python before 3.2 does not properly handle unsuccessful calls to the accept function, and does not have accompanying documentation describing how daemon applications should handle unsuccessful calls to the accept function, which makes it easier for remote attackers to conduct denial of service attacks that terminate these applications via network connections.",
            "family": "windows",
            "id": "oval:org.mitre.oval:def:12111",
            "status": "accepted",
            "submitted": "2010-11-18T10:50:19",
            "title": "Vulnerability in the asyncore module in Python before 3.2",
            "version": "76"
        }
    ],
    "ranking": [
        [
            {
                "circl": 3
            }
        ]
    ],
    "references": [
        "http://bugs.python.org/issue6706",
        "http://www.mandriva.com/security/advisories?name=MDVSA-2010:215",
        "http://www.mandriva.com/security/advisories?name=MDVSA-2010:216",
        "http://www.openwall.com/lists/oss-security/2010/09/09/6",
        "http://www.openwall.com/lists/oss-security/2010/09/11/2",
        "http://www.openwall.com/lists/oss-security/2010/09/22/3",
        "http://www.openwall.com/lists/oss-security/2010/09/24/3"
    ],
    "refmap": {
        "confirm": [
            "http://bugs.python.org/issue6706"
        ],
        "mandriva": [
            "MDVSA-2010:215",
            "MDVSA-2010:216"
        ],
        "mlist": [
            "[oss-security] 20100909 CVE Request -- Python -- accept() implementation in async core is broken => more subcases",
            "[oss-security] 20100910 Re: CVE Request -- Python -- accept() implementation in async core is broken => more subcases",
            "[oss-security] 20100922 Re: CVE Request -- Python -- accept() implementation in async core is broken => more subcases",
            "[oss-security] 20100924 Re: CVE Request -- Python -- accept() implementation in async core is broken => more subcases"
        ]
    },
    "summary": "The asyncore module in Python before 3.2 does not properly handle unsuccessful calls to the accept function, and does not have accompanying documentation describing how daemon applications should handle unsuccessful calls to the accept function, which makes it easier for remote attackers to conduct denial of service attacks that terminate these applications via network connections.",
    "vulnerable_configuration": [
        {
            "id": "cpe:2.3:a:python:python:2.6",
            "title": "Python 2.6"
        },
        {
            "id": "cpe:2.3:a:python:python:2.5.3",
            "title": "Python 2.5.3"
        },
        {
            "id": "cpe:2.3:a:python:python:2.6.1",
            "title": "Python 2.6.1"
        },
        {
            "id": "cpe:2.3:a:python:python:2.3.2",
            "title": "Python 2.3.2"
        },
        {
            "id": "cpe:2.3:a:python:python:2.3.1",
            "title": "Python 2.3.1"
        },
        {
            "id": "cpe:2.3:a:python:python:2.5.2",
            "title": "Python 2.5.2"
        },
        {
            "id": "cpe:2.3:a:python:python:2.4",
            "title": "Python 2.4"
        },
        {
            "id": "cpe:2.3:a:python:python:2.1.2",
            "title": "Python 2.1.2"
        },
        {
            "id": "cpe:2.3:a:python:python:2.1",
            "title": "Python 2.1"
        },
        {
            "id": "cpe:2.3:a:python:python:2.2.1",
            "title": "Python 2.2.1"
        },
        {
            "id": "cpe:2.3:a:python:python:2.2",
            "title": "Python 2.2"
        },
        {
            "id": "cpe:2.3:a:python:python:0.9.1",
            "title": "Python 0.9.1"
        },
        {
            "id": "cpe:2.3:a:python:python:2.3.4",
            "title": "Python 2.3.4"
        },
        {
            "id": "cpe:2.3:a:python:python:0.9.0",
            "title": "Python 0.9.0"
        },
        {
            "id": "cpe:2.3:a:python:python:2.3.5",
            "title": "Python 2.3.5"
        },
        {
            "id": "cpe:2.3:a:python:python:2.4.3",
            "title": "Python Python 2.4.3"
        },
        {
            "id": "cpe:2.3:a:python:python:2.0.1",
            "title": "Python 2.0.1"
        },
        {
            "id": "cpe:2.3:a:python:python:2.3",
            "title": "Python 2.3"
        },
        {
            "id": "cpe:2.3:a:python:python:1.6.1",
            "title": "Python 1.6.1"
        },
        {
            "id": "cpe:2.3:a:python:python:2.3.3",
            "title": "Python 2.3.3"
        },
        {
            "id": "cpe:2.3:a:python:python:1.6",
            "title": "Python 1.6"
        },
        {
            "id": "cpe:2.3:a:python:python:2.2.2",
            "title": "Python 2.2.2"
        },
        {
            "id": "cpe:2.3:a:python:python:2.0",
            "title": "Python 2.0"
        },
        {
            "id": "cpe:2.3:a:python:python:2.2.3",
            "title": "Python 2.2.3"
        },
        {
            "id": "cpe:2.3:a:python:python:1.2",
            "title": "Python 1.2"
        },
        {
            "id": "cpe:2.3:a:python:python:1.5.2",
            "title": "Python 1.5.2"
        },
        {
            "id": "cpe:2.3:a:python:python:1.3",
            "title": "Python 1.3"
        },
        {
            "id": "cpe:2.3:a:python:python:2.1.1",
            "title": "Python 2.1.1"
        },
        {
            "id": "cpe:2.3:a:python:python:3.0.1",
            "title": "Python 3.0.1"
        },
        {
            "id": "cpe:2.3:a:python:python:2.6.4",
            "title": "Python 2.6.4"
        },
        {
            "id": "cpe:2.3:a:python:python:3.1.1",
            "title": "Python 3.1.1"
        },
        {
            "id": "cpe:2.3:a:python:python:3.0",
            "title": "Python 3.0"
        },
        {
            "id": "cpe:2.3:a:python:python:2.3.7",
            "title": "Python 2.3.7"
        },
        {
            "id": "cpe:2.3:a:python:python:2.1.3",
            "title": "Python 2.1.3"
        },
        {
            "id": "cpe:2.3:a:python:python:2.5.4",
            "title": "Python 2.5.4"
        },
        {
            "id": "cpe:2.3:a:python:python:2.4.6",
            "title": "Python 2.4.6"
        },
        {
            "id": "cpe:2.3:a:python:python:2.5.1",
            "title": "Python 2.5.1"
        },
        {
            "id": "cpe:2.3:a:python:python:2.5",
            "title": "Python 2.5"
        },
        {
            "id": "cpe:2.3:a:python:python:2.4.4",
            "title": "Python 2.4.4"
        },
        {
            "id": "cpe:2.3:a:python:python:2.4.2",
            "title": "Python 2.4.2"
        },
        {
            "id": "cpe:2.3:a:python:python:2.4.1",
            "title": "Python 2.4.1"
        },
        {
            "id": "cpe:2.3:a:python:python:2.7",
            "title": "Python 2.7"
        },
        {
            "id": "cpe:2.3:a:python:python:3.1.2",
            "title": "Python 3.1.2"
        }
    ],
    "vulnerable_configuration_cpe_2_2": [
        "cpe:/a:python:python:2.6",
        "cpe:/a:python:python:2.5.3",
        "cpe:/a:python:python:2.6.1",
        "cpe:/a:python:python:2.3.2",
        "cpe:/a:python:python:2.3.1",
        "cpe:/a:python:python:2.5.2",
        "cpe:/a:python:python:2.4",
        "cpe:/a:python:python:2.1.2",
        "cpe:/a:python:python:2.1",
        "cpe:/a:python:python:2.2.1",
        "cpe:/a:python:python:2.2",
        "cpe:/a:python:python:0.9.1",
        "cpe:/a:python:python:2.3.4",
        "cpe:/a:python:python:0.9.0",
        "cpe:/a:python:python:2.3.5",
        "cpe:/a:python:python:2.4.3",
        "cpe:/a:python:python:2.0.1",
        "cpe:/a:python:python:2.3",
        "cpe:/a:python:python:1.6.1",
        "cpe:/a:python:python:2.3.3",
        "cpe:/a:python:python:1.6",
        "cpe:/a:python:python:2.2.2",
        "cpe:/a:python:python:2.0",
        "cpe:/a:python:python:2.2.3",
        "cpe:/a:python:python:1.2",
        "cpe:/a:python:python:1.5.2",
        "cpe:/a:python:python:1.3",
        "cpe:/a:python:python:2.1.1",
        "cpe:/a:python:python:3.0.1",
        "cpe:/a:python:python:2.6.4",
        "cpe:/a:python:python:3.1.1",
        "cpe:/a:python:python:3.0",
        "cpe:/a:python:python:2.3.7",
        "cpe:/a:python:python:2.1.3",
        "cpe:/a:python:python:2.5.4",
        "cpe:/a:python:python:2.4.6",
        "cpe:/a:python:python:2.5.1",
        "cpe:/a:python:python:2.5",
        "cpe:/a:python:python:2.4.4",
        "cpe:/a:python:python:2.4.2",
        "cpe:/a:python:python:2.4.1",
        "cpe:/a:python:python:2.7",
        "cpe:/a:python:python:3.1.2"
    ]
}