{
    "Modified": "2019-10-25T11:53:00",
    "Published": "2010-05-27T19:30:00",
    "access": {
        "authentication": "NONE",
        "complexity": "LOW",
        "vector": "NETWORK"
    },
    "assigner": "cve@mitre.org",
    "capec": [],
    "cvss": 5.0,
    "cvss-time": "2019-10-25T11:53:00",
    "cvss-vector": "AV:N/AC:L/Au:N/C:N/I:N/A:P",
    "cwe": "CWE-189",
    "id": "CVE-2010-1634",
    "impact": {
        "availability": "PARTIAL",
        "confidentiality": "NONE",
        "integrity": "NONE"
    },
    "last-modified": "2019-10-25T11:53:00",
    "redhat": {
        "advisories": [
            {
                "rhsa": {
                    "id": "RHSA-2011:0027"
                }
            }
        ],
        "rpms": [
            "python-0:2.4.3-43.el5",
            "python-debuginfo-0:2.4.3-43.el5",
            "python-devel-0:2.4.3-43.el5",
            "python-libs-0:2.4.3-43.el5",
            "python-tools-0:2.4.3-43.el5",
            "tkinter-0:2.4.3-43.el5",
            "python-0:2.3.4-14.10.el4",
            "python-debuginfo-0:2.3.4-14.10.el4",
            "python-devel-0:2.3.4-14.10.el4",
            "python-docs-0:2.3.4-14.10.el4",
            "python-tools-0:2.3.4-14.10.el4",
            "tkinter-0:2.3.4-14.10.el4"
        ]
    },
    "references": [
        "http://bugs.python.org/issue8674",
        "http://lists.apple.com/archives/Security-announce/2011//Oct/msg00003.html",
        "http://lists.fedoraproject.org/pipermail/package-announce/2010-June/042751.html",
        "http://lists.opensuse.org/opensuse-security-announce/2010-12/msg00006.html",
        "http://lists.opensuse.org/opensuse-security-announce/2011-01/msg00006.html",
        "http://secunia.com/advisories/39937",
        "http://secunia.com/advisories/40194",
        "http://secunia.com/advisories/42888",
        "http://secunia.com/advisories/43068",
        "http://secunia.com/advisories/50858",
        "http://secunia.com/advisories/51024",
        "http://secunia.com/advisories/51040",
        "http://secunia.com/advisories/51087",
        "http://support.apple.com/kb/HT5002",
        "http://svn.python.org/view?rev=81045&view=rev",
        "http://svn.python.org/view?rev=81079&view=rev",
        "http://www.redhat.com/support/errata/RHSA-2011-0027.html",
        "http://www.securityfocus.com/bid/40370",
        "http://www.ubuntu.com/usn/USN-1596-1",
        "http://www.ubuntu.com/usn/USN-1613-1",
        "http://www.ubuntu.com/usn/USN-1613-2",
        "http://www.ubuntu.com/usn/USN-1616-1",
        "http://www.vupen.com/english/advisories/2010/1448",
        "http://www.vupen.com/english/advisories/2011/0122",
        "http://www.vupen.com/english/advisories/2011/0212",
        "https://bugzilla.redhat.com/show_bug.cgi?id=590690"
    ],
    "refmap": {
        "apple": [
            "APPLE-SA-2011-10-12-3"
        ],
        "bid": [
            "40370"
        ],
        "confirm": [
            "http://bugs.python.org/issue8674",
            "http://support.apple.com/kb/HT5002",
            "http://svn.python.org/view?rev=81045&view=rev",
            "http://svn.python.org/view?rev=81079&view=rev",
            "https://bugzilla.redhat.com/show_bug.cgi?id=590690"
        ],
        "fedora": [
            "FEDORA-2010-9652"
        ],
        "secunia": [
            "39937",
            "40194",
            "42888",
            "43068",
            "50858",
            "51024",
            "51040",
            "51087"
        ],
        "suse": [
            "SUSE-SR:2010:024",
            "SUSE-SR:2011:002"
        ],
        "ubuntu": [
            "USN-1596-1",
            "USN-1613-1",
            "USN-1613-2",
            "USN-1616-1"
        ],
        "vupen": [
            "ADV-2010-1448",
            "ADV-2011-0122",
            "ADV-2011-0212"
        ]
    },
    "summary": "Multiple integer overflows in audioop.c in the audioop module in Python 2.6, 2.7, 3.1, and 3.2 allow context-dependent attackers to cause a denial of service (application crash) via a large fragment, as demonstrated by a call to audioop.lin2lin with a long string in the first argument, leading to a buffer overflow.  NOTE: this vulnerability exists because of an incorrect fix for CVE-2008-3143.5.",
    "vulnerable_configuration": [
        {
            "id": "cpe:2.3:a:python:python:3.1:*:*:*:*:*:*:*",
            "title": "cpe:2.3:a:python:python:3.1:*:*:*:*:*:*:*"
        },
        {
            "id": "cpe:2.3:a:python:python:3.2:*:*:*:*:*:*:*",
            "title": "cpe:2.3:a:python:python:3.2:*:*:*:*:*:*:*"
        }
    ],
    "vulnerable_configuration_cpe_2_2": [],
    "vulnerable_product": [
        "cpe:2.3:a:python:python:3.1:*:*:*:*:*:*:*",
        "cpe:2.3:a:python:python:3.2:*:*:*:*:*:*:*"
    ]
}