{
    "Modified": "2013-05-14T23:25:59.620-04:00",
    "Published": "2012-08-14T18:55:01.253-04:00",
    "access": {
        "authentication": "NONE",
        "complexity": "LOW",
        "vector": "NETWORK"
    },
    "cvss": 6.4,
    "cvss-time": "2012-08-15T10:06:00.000-04:00",
    "id": "CVE-2012-2135",
    "impact": {
        "availability": "PARTIAL",
        "confidentiality": "PARTIAL",
        "integrity": "NONE"
    },
    "map_cve_nessus": {
        "nessus_script_family": "Ubuntu Local Security Checks",
        "nessus_script_file": "ubuntu_USN-1616-1.nasl",
        "nessus_script_id": "62700",
        "nessus_script_name": "Ubuntu 10.04 LTS / 11.04 : python3.1 vulnerabilities (USN-1616-1)"
    },
    "map_cve_openvas": {
        "openvas_script_family": "Ubuntu Local Security Checks",
        "openvas_script_file": "gb_ubuntu_USN_1616_1.nasl",
        "openvas_script_id": "841199",
        "openvas_script_name": "Ubuntu Update for python3.1 USN-1616-1"
    },
    "map_cve_oval": {
        "cpeid": "",
        "ovalclass": "patch",
        "ovalid": "oval:org.mitre.oval:def:17837",
        "ovaltitle": "USN-1615-1 -- python3.2 vulnerabilities"
    },
    "map_cve_scip": {
        "scipid": "61620",
        "sciplink": "http://www.scip.ch/en/?vuldb.61620"
    },
    "map_cve_ubuntu": {
        "ubuntuid": "USN-1616-1"
    },
    "ranking": [
        [
            {
                "circl": 2
            }
        ]
    ],
    "references": [
        "http://www.ubuntu.com/usn/USN-1616-1",
        "http://www.ubuntu.com/usn/USN-1615-1",
        "http://www.openwall.com/lists/oss-security/2012/04/25/4",
        "http://www.openwall.com/lists/oss-security/2012/04/25/2",
        "http://bugs.python.org/issue14579",
        "http://bugs.debian.org/cgi-bin/bugreport.cgi?bug=670389"
    ],
    "summary": "The utf-16 decoder in Python 3.1 through 3.3 does not update the aligned_end variable after calling the unicode_decode_call_errorhandler function, which allows remote attackers to obtain sensitive information (process memory) or cause a denial of service (memory corruption and crash) via unspecified vectors.",
    "vulnerable_configuration": [
        {
            "id": "cpe:2.3:a:python:python:3.1",
            "title": "Python 3.1"
        },
        {
            "id": "cpe:2.3:a:python:python:3.1.1",
            "title": "Python 3.1.1"
        },
        {
            "id": "cpe:2.3:a:python:python:3.1.2",
            "title": "Python 3.1.2"
        },
        {
            "id": "cpe:2.3:a:python:python:3.2.2150",
            "title": "Python 3.2.2150"
        },
        {
            "id": "cpe:2.3:a:python:python:3.2:alpha",
            "title": "Python 3.2-alpha"
        },
        {
            "id": "cpe:2.3:a:python:python:3.1.5",
            "title": "Python 3.1.5"
        },
        {
            "id": "cpe:2.3:a:python:python:3.2.3",
            "title": "Python 3.2.3"
        },
        {
            "id": "cpe:2.3:a:python:python:3.3",
            "title": "Python 3.3"
        },
        {
            "id": "cpe:2.3:a:python:python:3.3:beta2",
            "title": "Python 3.3 beta 2"
        }
    ],
    "vulnerable_configuration_cpe_2_2": [
        "cpe:/a:python:python:3.1",
        "cpe:/a:python:python:3.1.1",
        "cpe:/a:python:python:3.1.2",
        "cpe:/a:python:python:3.2.2150",
        "cpe:/a:python:python:3.2:alpha",
        "cpe:/a:python:python:3.1.5",
        "cpe:/a:python:python:3.2.3",
        "cpe:/a:python:python:3.3",
        "cpe:/a:python:python:3.3:beta2"
    ]
}