{
    "Modified": "2013-05-14T23:25:59.620000",
    "Published": "2012-08-14T18:55:01.253000",
    "access": {
        "authentication": "NONE",
        "complexity": "LOW",
        "vector": "NETWORK"
    },
    "cvss": 6.4,
    "cvss-time": "2012-08-15T10:06:00",
    "id": "CVE-2012-2135",
    "impact": {
        "availability": "PARTIAL",
        "confidentiality": "PARTIAL",
        "integrity": "NONE"
    },
    "nessus": [
        {
            "NASL family": "SuSE Local Security Checks",
            "NASL id": "OPENSUSE-2012-380.NASL",
            "description": "python3 was fixed for :\n\n  - Fix bnc#758993 - CVE-2012-2135: python3 utf-16 decoder     unicode_decode_call_errorhandler aligned_end is not     updated",
            "last seen": "2019-02-21",
            "modified": "2018-11-10",
            "plugin id": "74675",
            "published": "2014-06-13",
            "reporter": "Tenable",
            "source": "https://www.tenable.com/plugins/index.php?view=single&id=74675",
            "title": "openSUSE Security Update : python3 (openSUSE-SU-2012:0861-1)"
        },
        {
            "NASL family": "Ubuntu Local Security Checks",
            "NASL id": "UBUNTU_USN-1615-1.NASL",
            "description": "It was discovered that Python distutils contained a race condition when creating the ~/.pypirc file. A local attacker could exploit this to obtain sensitive information. (CVE-2011-4944)\n\nIt was discovered that SimpleXMLRPCServer did not properly validate its input when handling HTTP POST requests. A remote attacker could exploit this to cause a denial of service via excessive CPU utilization. This issue only affected Ubuntu 11.04 and 11.10.\n(CVE-2012-0845)\n\nIt was discovered that Python was susceptible to hash algorithm attacks. An attacker could cause a denial of service under certian circumstances. This update adds the '-R' command line option and honors setting the PYTHONHASHSEED environment variable to 'random' to salt str and datetime objects with an unpredictable value. This issue only affected Ubuntu 11.04 and 11.10. (CVE-2012-1150)\n\nSerhiy Storchaka discovered that the UTF16 decoder in Python did not properly reset internal variables after error handling. An attacker could exploit this to cause a denial of service via memory corruption.\nThis issue did not affect Ubuntu 12.10. (CVE-2012-2135).\n\nNote that Tenable Network Security has extracted the preceding description block directly from the Ubuntu security advisory. Tenable has attempted to automatically clean and format it as much as possible without introducing additional issues.",
            "last seen": "2019-02-21",
            "modified": "2018-12-01",
            "plugin id": "62677",
            "published": "2012-10-24",
            "reporter": "Tenable",
            "source": "https://www.tenable.com/plugins/index.php?view=single&id=62677",
            "title": "Ubuntu 11.04 / 11.10 / 12.04 LTS / 12.10 : python3.2 vulnerabilities (USN-1615-1)"
        },
        {
            "NASL family": "Ubuntu Local Security Checks",
            "NASL id": "UBUNTU_USN-1616-1.NASL",
            "description": "It was discovered that Python would prepend an empty string to sys.path under certain circumstances. A local attacker with write access to the current working directory could exploit this to execute arbitrary code. This issue only affected Ubuntu 10.04 LTS.\n(CVE-2008-5983)\n\nIt was discovered that the audioop module did not correctly perform input validation. If a user or automated system were tricked into opening a crafted audio file, an attacker could cause a denial of service via application crash. These issues only affected Ubuntu 10.04 LTS. (CVE-2010-1634, CVE-2010-2089)\n\nIt was discovered that Python distutils contained a race condition when creating the ~/.pypirc file. A local attacker could exploit this to obtain sensitive information. (CVE-2011-4944)\n\nIt was discovered that SimpleXMLRPCServer did not properly validate its input when handling HTTP POST requests. A remote attacker could exploit this to cause a denial of service via excessive CPU utilization. (CVE-2012-0845)\n\nIt was discovered that Python was susceptible to hash algorithm attacks. An attacker could cause a denial of service under certian circumstances. This update adds the '-R' command line option and honors setting the PYTHONHASHSEED environment variable to 'random' to salt str and datetime objects with an unpredictable value.\n(CVE-2012-1150)\n\nSerhiy Storchaka discovered that the UTF16 decoder in Python did not properly reset internal variables after error handling. An attacker could exploit this to cause a denial of service via memory corruption.\n(CVE-2012-2135).\n\nNote that Tenable Network Security has extracted the preceding description block directly from the Ubuntu security advisory. Tenable has attempted to automatically clean and format it as much as possible without introducing additional issues.",
            "last seen": "2019-02-21",
            "modified": "2018-12-01",
            "plugin id": "62700",
            "published": "2012-10-25",
            "reporter": "Tenable",
            "source": "https://www.tenable.com/plugins/index.php?view=single&id=62700",
            "title": "Ubuntu 10.04 LTS / 11.04 : python3.1 vulnerabilities (USN-1616-1)"
        }
    ],
    "ranking": [
        [
            {
                "circl": 3
            }
        ]
    ],
    "references": [
        "http://bugs.debian.org/cgi-bin/bugreport.cgi?bug=670389",
        "http://bugs.python.org/issue14579",
        "http://www.openwall.com/lists/oss-security/2012/04/25/2",
        "http://www.openwall.com/lists/oss-security/2012/04/25/4",
        "http://www.ubuntu.com/usn/USN-1615-1",
        "http://www.ubuntu.com/usn/USN-1616-1"
    ],
    "refmap": {
        "misc": [
            "http://bugs.debian.org/cgi-bin/bugreport.cgi?bug=670389",
            "http://bugs.python.org/issue14579"
        ],
        "mlist": [
            "[oss-security] 20120425 CVE Request: Python 3.2/3.3 utf-16 decoder unicode_decode_call_errorhandler aligned_end is not updated",
            "[oss-security] 20120425 Re: CVE Request: Python 3.2/3.3 utf-16 decoder unicode_decode_call_errorhandler aligned_end is not updated"
        ],
        "secunia": [
            "51087",
            "51089"
        ],
        "ubuntu": [
            "USN-1615-1",
            "USN-1616-1"
        ]
    },
    "summary": "The utf-16 decoder in Python 3.1 through 3.3 does not update the aligned_end variable after calling the unicode_decode_call_errorhandler function, which allows remote attackers to obtain sensitive information (process memory) or cause a denial of service (memory corruption and crash) via unspecified vectors.",
    "vulnerable_configuration": [
        {
            "id": "cpe:2.3:a:python:python:3.1",
            "title": "Python 3.1"
        },
        {
            "id": "cpe:2.3:a:python:python:3.1.1",
            "title": "Python 3.1.1"
        },
        {
            "id": "cpe:2.3:a:python:python:3.1.2",
            "title": "Python 3.1.2"
        },
        {
            "id": "cpe:2.3:a:python:python:3.2.2150",
            "title": "Python 3.2.2150"
        },
        {
            "id": "cpe:2.3:a:python:python:3.2:alpha",
            "title": "Python 3.2-alpha"
        },
        {
            "id": "cpe:2.3:a:python:python:3.1.5",
            "title": "Python 3.1.5"
        },
        {
            "id": "cpe:2.3:a:python:python:3.2.3",
            "title": "Python 3.2.3"
        },
        {
            "id": "cpe:2.3:a:python:python:3.3",
            "title": "Python 3.3"
        },
        {
            "id": "cpe:2.3:a:python:python:3.3:beta2",
            "title": "Python 3.3 beta 2"
        }
    ],
    "vulnerable_configuration_cpe_2_2": [
        "cpe:/a:python:python:3.1",
        "cpe:/a:python:python:3.1.1",
        "cpe:/a:python:python:3.1.2",
        "cpe:/a:python:python:3.2.2150",
        "cpe:/a:python:python:3.2:alpha",
        "cpe:/a:python:python:3.1.5",
        "cpe:/a:python:python:3.2.3",
        "cpe:/a:python:python:3.3",
        "cpe:/a:python:python:3.3:beta2"
    ]
}